Workbook

Sheet Executive Dashboard
A1: PIPELINE EXECUTIVE DASHBOARD
A3: ="Period: May-26 to Dec-27 | Currency: SAR | Last refresh: " & TEXT('Pipeline Report'!H2,"dd-mmm-yyyy") -> Period: May-26 to Dec-27 | Currency: SAR | Last refresh: 05-May-2026
A5: PIPELINE — WEIGHTED | D5: MATERIALIZING (75%+ PROB) | G5: PROJECTED GP — WEIGHTED | J5: FREE CAPACITY BASELINE
A6: ='Pipeline Report'!AH67 -> 43332714 | D6: =SUMIFS('Pipeline Report'!AI6:AI65,'Pipeline Report'!E6:E65,">=0.75") -> 20217983 | G6: ='Pipeline Report'!AH137 -> 10833178 | J6: ='Pipeline Report'!G171 -> 88870
A8: ="Unweighted: " & TEXT('Pipeline Report'!AH66,"#,##0,,") & "M SAR" -> Unweighted: 64M SAR | D8: ="Across " & SUMPRODUCT(('Pipeline Report'!E6:E65>=0.75)*('Pipeline Report'!B6:B65<>"")) & " near-term deals" -> Across 18 near-term deals | G8: ="Unweighted GP: " & TEXT('Pipeline Report'!AH136,"#,##0,,") & "M | Margin: " & TEXT('Pipeline Report'!AH138,"0.0%") -> Unweighted GP: 16M | Margin: 25.0% | J8: ="Committed by Dec-26: " & TEXT('Pipeline Report'!S183,"#,##0") & " pallets (" & TEXT('Pipeline Report'!S185,"0.0%") & " utilization)" -> Committed by Dec-26: 24,220 pallets (27.3% utilization)
A10: 💰 FORECAST vs BUDGET — FY26
A11: FY26 REVENUE GAP | D11: FY26 GP GAP | G11: UNSOLD CAPACITY VALUE
A12: ='Forecast +75% - 100%'!P11 -> -12255269 | D12: ='Forecast +75% - 100%'!P19 -> -6454619.6 | G12: ='Forecast +75% - 100%'!P23 -> 3148980
A14: ="Forecast: " & TEXT('Forecast +75% - 100%'!P9,"#,##0.0,,") & "M | Budget: " & TEXT('Forecast +75% - 100%'!P10,"#,##0.0,,") & "M SAR" -> Forecast: 92.8M | Budget: 106.0M SAR | D14: ="Forecast GP: " & TEXT('Forecast +75% - 100%'!P17,"#,##0.0,,") & "M | Budget GP: " & TEXT('Forecast +75% - 100%'!P18,"#,##0.0,,") & "M SAR" -> Forecast GP: 7.1M | Budget GP: 13.6M SAR | G14: ="If " & TEXT('Forecast +75% - 100%'!O21,"#,##0") & " pallets stay unsold @ " & TEXT('Forecast +75% - 100%'!O22,"#,##0") & " SAR/pallet/mo" -> If 64,650 pallets stay unsold @ 48 SAR/pallet/mo
A16: 📊 PIPELINE BY STAGE
A17: Stage | B17: Probability | C17: # Deals | D17: Pipeline (Unwtd) | E17: Pipeline (Wtd) | F17: % of Total Wtd
A18: Contract Negotiation | B18: 0.9 | C18: =COUNTIF('Pipeline Report'!D6:D65,"Contract Negotiation") -> 3 | D18: =SUMIF('Pipeline Report'!D6:D65,"Contract Negotiation",'Pipeline Report'!AH6:AH65) -> 7100000 | E18: =SUMIF('Pipeline Report'!D6:D65,"Contract Negotiation",'Pipeline Report'!AI6:AI65) -> 6390000 | F18: =IFERROR(E18/$E$25,0) -> 0.14746365
A19: Shortlisted | B19: 0.75 | C19: =COUNTIF('Pipeline Report'!D6:D65,"Shortlisted") -> 5 | D19: =SUMIF('Pipeline Report'!D6:D65,"Shortlisted",'Pipeline Report'!AH6:AH65) -> 5578200 | E19: =SUMIF('Pipeline Report'!D6:D65,"Shortlisted",'Pipeline Report'!AI6:AI65) -> 4183650 | F19: =IFERROR(E19/$E$25,0) -> 0.09654715
A20: Proposal Sent | B20: 0.6 | C20: =COUNTIF('Pipeline Report'!D6:D65,"Proposal Sent") -> 25 | D20: =SUMIF('Pipeline Report'!D6:D65,"Proposal Sent",'Pipeline Report'!AH6:AH65) -> 36427328 | E20: =SUMIF('Pipeline Report'!D6:D65,"Proposal Sent",'Pipeline Report'!AI6:AI65) -> 21856397 | F20: =IFERROR(E20/$E$25,0) -> 0.50438561
A21: Qualified | B21: 0.4 | C21: =COUNTIF('Pipeline Report'!D6:D65,"Qualified") -> 1 | D21: =SUMIF('Pipeline Report'!D6:D65,"Qualified",'Pipeline Report'!AH6:AH65) -> 1345833.3 | E21: =SUMIF('Pipeline Report'!D6:D65,"Qualified",'Pipeline Report'!AI6:AI65) -> 538333.33 | F21: =IFERROR(E21/$E$25,0) -> 0.012423255
A22: Prospecting | B22: 0.2 | C22: =COUNTIF('Pipeline Report'!D6:D65,"Prospecting") -> 1 | D22: =SUMIF('Pipeline Report'!D6:D65,"Prospecting",'Pipeline Report'!AH6:AH65) -> 3600000 | E22: =SUMIF('Pipeline Report'!D6:D65,"Prospecting",'Pipeline Report'!AI6:AI65) -> 720000 | F22: =IFERROR(E22/$E$25,0) -> 0.016615622
A23: Closed Won | B23: 1 | C23: =COUNTIF('Pipeline Report'!D6:D65,"Closed Won") -> 10 | D23: =SUMIF('Pipeline Report'!D6:D65,"Closed Won",'Pipeline Report'!AH6:AH65) -> 9644333.3 | E23: =SUMIF('Pipeline Report'!D6:D65,"Closed Won",'Pipeline Report'!AI6:AI65) -> 9644333.3 | F23: =IFERROR(E23/$E$25,0) -> 0.22256472
A24: Closed Lost | B24: 0 | C24: =COUNTIF('Pipeline Report'!D6:D65,"Closed Lost") -> 0 | D24: =SUMIF('Pipeline Report'!D6:D65,"Closed Lost",'Pipeline Report'!AH6:AH65) -> 0 | E24: =SUMIF('Pipeline Report'!D6:D65,"Closed Lost",'Pipeline Report'!AI6:AI65) -> 0 | F24: =IFERROR(E24/$E$25,0) -> 0
A25: TOTAL | C25: =SUM(C18:C24) -> 45 | D25: =SUM(D18:D24) -> 63695695 | E25: =SUM(E18:E24) -> 43332714 | F25: =SUM(F18:F24) -> 1
A28: 🎯 TOP DEALS BY WEIGHTED VALUE — what's most likely to materialize
A29: # | B29: Customer | C29: Stage | D29: Probability | E29: Warehouse | F29: Go-Live | G29: ACV (SAR) | H29: Weighted (SAR)
A30: 1 | B30: =IFERROR(INDEX('Pipeline Report'!B6:B65,MATCH(LARGE('Pipeline Report'!AI6:AI65,1),'Pipeline Report'!AI6:AI65,0)),"") -> Kuehne & Nagel | C30: =IFERROR(INDEX('Pipeline Report'!D6:D65,MATCH(LARGE('Pipeline Report'!AI6:AI65,1),'Pipeline Report'!AI6:AI65,0)),"") -> Proposal Sent | D30: =IFERROR(INDEX('Pipeline Report'!E6:E65,MATCH(LARGE('Pipeline Report'!AI6:AI65,1),'Pipeline Report'!AI6:AI65,0)),0) -> 0.6 | E30: =IFERROR(INDEX('Pipeline Report'!F6:F65,MATCH(LARGE('Pipeline Report'!AI6:AI65,1),'Pipeline Report'!AI6:AI65,0)),"") -> RUH Tayba | F30: =IFERROR(INDEX('Pipeline Report'!G6:G65,MATCH(LARGE('Pipeline Report'!AI6:AI65,1),'Pipeline Report'!AI6:AI65,0)),"") -> 46327 | G30: =IFERROR(INDEX('Pipeline Report'!H6:H65,MATCH(LARGE('Pipeline Report'!AI6:AI65,1),'Pipeline Report'!AI6:AI65,0)),0) -> 6102000 | H30: =IFERROR(LARGE('Pipeline Report'!AI6:AI65,1),0) -> 4271400
A31: 2 | B31: =IFERROR(INDEX('Pipeline Report'!B6:B65,MATCH(LARGE('Pipeline Report'!AI6:AI65,2),'Pipeline Report'!AI6:AI65,0)),"") -> Tejoury | C31: =IFERROR(INDEX('Pipeline Report'!D6:D65,MATCH(LARGE('Pipeline Report'!AI6:AI65,2),'Pipeline Report'!AI6:AI65,0)),"") -> Proposal Sent | D31: =IFERROR(INDEX('Pipeline Report'!E6:E65,MATCH(LARGE('Pipeline Report'!AI6:AI65,2),'Pipeline Report'!AI6:AI65,0)),0) -> 0.6 | E31: =IFERROR(INDEX('Pipeline Report'!F6:F65,MATCH(LARGE('Pipeline Report'!AI6:AI65,2),'Pipeline Report'!AI6:AI65,0)),"") -> Jeddah Modon 3A | F31: =IFERROR(INDEX('Pipeline Report'!G6:G65,MATCH(LARGE('Pipeline Report'!AI6:AI65,2),'Pipeline Report'!AI6:AI65,0)),"") -> 46204 | G31: =IFERROR(INDEX('Pipeline Report'!H6:H65,MATCH(LARGE('Pipeline Report'!AI6:AI65,2),'Pipeline Report'!AI6:AI65,0)),0) -> 4400000 | H31: =IFERROR(LARGE('Pipeline Report'!AI6:AI65,2),0) -> 3960000
A32: 3 | B32: =IFERROR(INDEX('Pipeline Report'!B6:B65,MATCH(LARGE('Pipeline Report'!AI6:AI65,3),'Pipeline Report'!AI6:AI65,0)),"") -> NALCO Ecolab | C32: =IFERROR(INDEX('Pipeline Report'!D6:D65,MATCH(LARGE('Pipeline Report'!AI6:AI65,3),'Pipeline Report'!AI6:AI65,0)),"") -> Contract Negotiation | D32: =IFERROR(INDEX('Pipeline Report'!E6:E65,MATCH(LARGE('Pipeline Report'!AI6:AI65,3),'Pipeline Report'!AI6:AI65,0)),0) -> 0.9 | E32: =IFERROR(INDEX('Pipeline Report'!F6:F65,MATCH(LARGE('Pipeline Report'!AI6:AI65,3),'Pipeline Report'!AI6:AI65,0)),"") -> Dammam 2nd Ind -Tad WH | F32: =IFERROR(INDEX('Pipeline Report'!G6:G65,MATCH(LARGE('Pipeline Report'!AI6:AI65,3),'Pipeline Report'!AI6:AI65,0)),"") -> 46174 | G32: =IFERROR(INDEX('Pipeline Report'!H6:H65,MATCH(LARGE('Pipeline Report'!AI6:AI65,3),'Pipeline Report'!AI6:AI65,0)),0) -> 2400000 | H32: =IFERROR(LARGE('Pipeline Report'!AI6:AI65,3),0) -> 3420000
A33: 4 | B33: =IFERROR(INDEX('Pipeline Report'!B6:B65,MATCH(LARGE('Pipeline Report'!AI6:AI65,4),'Pipeline Report'!AI6:AI65,0)),"") -> PSA-BDP | C33: =IFERROR(INDEX('Pipeline Report'!D6:D65,MATCH(LARGE('Pipeline Report'!AI6:AI65,4),'Pipeline Report'!AI6:AI65,0)),"") -> Closed Won | D33: =IFERROR(INDEX('Pipeline Report'!E6:E65,MATCH(LARGE('Pipeline Report'!AI6:AI65,4),'Pipeline Report'!AI6:AI65,0)),0) -> 1 | E33: =IFERROR(INDEX('Pipeline Report'!F6:F65,MATCH(LARGE('Pipeline Report'!AI6:AI65,4),'Pipeline Report'!AI6:AI65,0)),"") -> Subcontractor | F33: =IFERROR(INDEX('Pipeline Report'!G6:G65,MATCH(LARGE('Pipeline Report'!AI6:AI65,4),'Pipeline Report'!AI6:AI65,0)),"") -> 46067 | G33: =IFERROR(INDEX('Pipeline Report'!H6:H65,MATCH(LARGE('Pipeline Report'!AI6:AI65,4),'Pipeline Report'!AI6:AI65,0)),0) -> 1800000 | H33: =IFERROR(LARGE('Pipeline Report'!AI6:AI65,4),0) -> 3000000
A34: 5 | B34: =IFERROR(INDEX('Pipeline Report'!B6:B65,MATCH(LARGE('Pipeline Report'!AI6:AI65,5),'Pipeline Report'!AI6:AI65,0)),"") -> Saudi National Bank | C34: =IFERROR(INDEX('Pipeline Report'!D6:D65,MATCH(LARGE('Pipeline Report'!AI6:AI65,5),'Pipeline Report'!AI6:AI65,0)),"") -> Proposal Sent | D34: =IFERROR(INDEX('Pipeline Report'!E6:E65,MATCH(LARGE('Pipeline Report'!AI6:AI65,5),'Pipeline Report'!AI6:AI65,0)),0) -> 0.6 | E34: =IFERROR(INDEX('Pipeline Report'!F6:F65,MATCH(LARGE('Pipeline Report'!AI6:AI65,5),'Pipeline Report'!AI6:AI65,0)),"") -> Contract Logistics | F34: =IFERROR(INDEX('Pipeline Report'!G6:G65,MATCH(LARGE('Pipeline Report'!AI6:AI65,5),'Pipeline Report'!AI6:AI65,0)),"") -> 46157 | G34: =IFERROR(INDEX('Pipeline Report'!H6:H65,MATCH(LARGE('Pipeline Report'!AI6:AI65,5),'Pipeline Report'!AI6:AI65,0)),0) -> 1975386 | H34: =IFERROR(LARGE('Pipeline Report'!AI6:AI65,5),0) -> 1975386
A35: 6 | B35: =IFERROR(INDEX('Pipeline Report'!B6:B65,MATCH(LARGE('Pipeline Report'!AI6:AI65,6),'Pipeline Report'!AI6:AI65,0)),"") -> Kuehne & Nagel | C35: =IFERROR(INDEX('Pipeline Report'!D6:D65,MATCH(LARGE('Pipeline Report'!AI6:AI65,6),'Pipeline Report'!AI6:AI65,0)),"") -> Proposal Sent | D35: =IFERROR(INDEX('Pipeline Report'!E6:E65,MATCH(LARGE('Pipeline Report'!AI6:AI65,6),'Pipeline Report'!AI6:AI65,0)),0) -> 0.6 | E35: =IFERROR(INDEX('Pipeline Report'!F6:F65,MATCH(LARGE('Pipeline Report'!AI6:AI65,6),'Pipeline Report'!AI6:AI65,0)),"") -> RUH Tayba | F35: =IFERROR(INDEX('Pipeline Report'!G6:G65,MATCH(LARGE('Pipeline Report'!AI6:AI65,6),'Pipeline Report'!AI6:AI65,0)),"") -> 46204 | G35: =IFERROR(INDEX('Pipeline Report'!H6:H65,MATCH(LARGE('Pipeline Report'!AI6:AI65,6),'Pipeline Report'!AI6:AI65,0)),0) -> 2025000 | H35: =IFERROR(LARGE('Pipeline Report'!AI6:AI65,6),0) -> 1822500
A36: 7 | B36: =IFERROR(INDEX('Pipeline Report'!B6:B65,MATCH(LARGE('Pipeline Report'!AI6:AI65,7),'Pipeline Report'!AI6:AI65,0)),"") -> Al Nahdi | C36: =IFERROR(INDEX('Pipeline Report'!D6:D65,MATCH(LARGE('Pipeline Report'!AI6:AI65,7),'Pipeline Report'!AI6:AI65,0)),"") -> Contract Negotiation | D36: =IFERROR(INDEX('Pipeline Report'!E6:E65,MATCH(LARGE('Pipeline Report'!AI6:AI65,7),'Pipeline Report'!AI6:AI65,0)),0) -> 0.9 | E36: =IFERROR(INDEX('Pipeline Report'!F6:F65,MATCH(LARGE('Pipeline Report'!AI6:AI65,7),'Pipeline Report'!AI6:AI65,0)),"") -> Jeddah Modon 3A | F36: =IFERROR(INDEX('Pipeline Report'!G6:G65,MATCH(LARGE('Pipeline Report'!AI6:AI65,7),'Pipeline Report'!AI6:AI65,0)),"") -> 46143 | G36: =IFERROR(INDEX('Pipeline Report'!H6:H65,MATCH(LARGE('Pipeline Report'!AI6:AI65,7),'Pipeline Report'!AI6:AI65,0)),0) -> 1080000 | H36: =IFERROR(LARGE('Pipeline Report'!AI6:AI65,7),0) -> 1620000
A37: 8 | B37: =IFERROR(INDEX('Pipeline Report'!B6:B65,MATCH(LARGE('Pipeline Report'!AI6:AI65,8),'Pipeline Report'!AI6:AI65,0)),"") -> Maaden | C37: =IFERROR(INDEX('Pipeline Report'!D6:D65,MATCH(LARGE('Pipeline Report'!AI6:AI65,8),'Pipeline Report'!AI6:AI65,0)),"") -> Closed Won | D37: =IFERROR(INDEX('Pipeline Report'!E6:E65,MATCH(LARGE('Pipeline Report'!AI6:AI65,8),'Pipeline Report'!AI6:AI65,0)),0) -> 1 | E37: =IFERROR(INDEX('Pipeline Report'!F6:F65,MATCH(LARGE('Pipeline Report'!AI6:AI65,8),'Pipeline Report'!AI6:AI65,0)),"") -> Jubail 1 | F37: =IFERROR(INDEX('Pipeline Report'!G6:G65,MATCH(LARGE('Pipeline Report'!AI6:AI65,8),'Pipeline Report'!AI6:AI65,0)),"") -> 46054 | G37: =IFERROR(INDEX('Pipeline Report'!H6:H65,MATCH(LARGE('Pipeline Report'!AI6:AI65,8),'Pipeline Report'!AI6:AI65,0)),0) -> 960000 | H37: =IFERROR(LARGE('Pipeline Report'!AI6:AI65,8),0) -> 1600000
A39: 🏭 WAREHOUSE CAPACITY — utilization at end of 2026
A40: Warehouse | B40: Baseline Free Space | C40: Committed (Dec-26) | D40: Remaining (Dec-26) | E40: Utilization %
A41: Dammam Port | B41: ='Pipeline Report'!G161 -> 4973 | C41: ='Pipeline Report'!S173 -> 300 | D41: ='Pipeline Report'!S161 -> 4673 | E41: =IFERROR(C41/B41,0) -> 0.060325759
A42: Dammam 2nd Ind | B42: ='Pipeline Report'!G162 -> 10047 | C42: ='Pipeline Report'!S174 -> 7090 | D42: ='Pipeline Report'!S162 -> 2957 | E42: =IFERROR(C42/B42,0) -> 0.70568329
A43: Jubail 1 | B43: ='Pipeline Report'!G163 -> 23706 | C43: ='Pipeline Report'!S175 -> 4330 | D43: ='Pipeline Report'!S163 -> 19376 | E43: =IFERROR(C43/B43,0) -> 0.18265418
A44: Jubail 2 | B44: ='Pipeline Report'!G164 -> 19247 | C44: ='Pipeline Report'!S176 -> 0 | D44: ='Pipeline Report'!S164 -> 19247 | E44: =IFERROR(C44/B44,0) -> 0
A45: Jubail Total | B45: ='Pipeline Report'!G165 -> 42953 | C45: ='Pipeline Report'!S177 -> 4330 | D45: ='Pipeline Report'!S165 -> 38623 | E45: =IFERROR(C45/B45,0) -> 0.10080786
A46: Jeddah Modon 3A | B46: ='Pipeline Report'!G166 -> 19713 | C46: ='Pipeline Report'!S178 -> 4500 | D46: ='Pipeline Report'!S166 -> 15213 | E46: =IFERROR(C46/B46,0) -> 0.22827576
A47: Jeddah Modon 3B | B47: ='Pipeline Report'!G167 -> 686 | C47: ='Pipeline Report'!S179 -> 5500 | D47: ='Pipeline Report'!S167 -> -4814 | E47: =IFERROR(C47/B47,0) -> 8.0174927
A48: RUH Tayba | B48: ='Pipeline Report'!G168 -> 2998 | C48: ='Pipeline Report'!S180 -> 0 | D48: ='Pipeline Report'!S168 -> 2998 | E48: =IFERROR(C48/B48,0) -> 0
A49: Subcontractor | B49: ='Pipeline Report'!G169 -> 7500 | C49: ='Pipeline Report'!S181 -> 2500 | D49: ='Pipeline Report'!S169 -> 5000 | E49: =IFERROR(C49/B49,0) -> 0.33333333
...

Sheet Pipeline Report
A1: PIPELINE ROLLING PROFITABILITY REPORT
A2: Period: | B2: May-26 to Dec-27 (20 months) | D2: Currency: | E2: SAR | G2: Last Updated: | H2: 05-May-2026 | J2: Source: | K2: Hala YTD WH Pipeline (Hano Oberholzer, 05-May-2026)
A4: 1. PIPELINE OPPORTUNITIES (Revenue)
A5: # | B5: Customer / Opportunity | C5: Opportunity Owner | D5: Stage | E5: Probability | F5: Warehouse Location | G5: Ops Go-Live Date | H5: Annual Contract Value | I5: Expected Revenue (Current Yr) | J5: Volume - Pallets | K5: Volume - SQM | L5: May-26 | M5: Jun-26 | N5: Jul-26 | O5: Aug-26 | P5: Sep-26 | Q5: Oct-26 | R5: Nov-26 | S5: Dec-26 | T5: 2026 Total | U5: Jan-27 | V5: Feb-27 | W5: Mar-27 | X5: Apr-27 | Y5: May-27 | Z5: Jun-27 | AA5: Jul-27 | AB5: Aug-27 | AC5: Sep-27 | AD5: Oct-27 | AE5: Nov-27 | AF5: Dec-27 | AG5: 2027 Total | AH5: Grand Total | AI5: Weighted Total | AJ5: Notes
A6: 1 | B6: =IF('Pipeline Data Input'!D3="","",'Pipeline Data Input'!D3) -> SLB | C6: =IF('Pipeline Data Input'!E3="","",'Pipeline Data Input'!E3) -> Yazan Darwish | D6: =IF('Pipeline Data Input'!J3="","",'Pipeline Data Input'!J3) -> Prospecting | E6: =IFERROR(VLOOKUP(D6,$B$211:$C$217,2,FALSE()),0) -> 0.2 | F6: =IF('Pipeline Data Input'!B3="","",IFERROR(VLOOKUP('Pipeline Data Input'!B3,'Pipeline Data Input'!$A$66:$B$80,2,FALSE()),'Pipeline Data Input'!B3)) -> Dammam 2nd Ind -Tad WH | G6: =IF('Pipeline Data Input'!K3="","",'Pipeline Data Input'!K3) -> 46204 | H6: =IF('Pipeline Data Input'!I3="",0,'Pipeline Data Input'!I3) -> 2400000 | I6: =T6 -> 1200000 | J6: =IF('Pipeline Data Input'!F3="",0,'Pipeline Data Input'!F3) -> 4000 | K6: =IF('Pipeline Data Input'!G3="",0,'Pipeline Data Input'!G3) -> 0 | L6: =IF(OR(G6="",H6=""),0,IF(DATE(2026,5,1)>=DATE(YEAR(G6),MONTH(G6),1),H6/12,0)) -> 0 | M6: =IF(OR(G6="",H6=""),0,IF(DATE(2026,6,1)>=DATE(YEAR(G6),MONTH(G6),1),H6/12,0)) -> 0 | N6: =IF(OR(G6="",H6=""),0,IF(DATE(2026,7,1)>=DATE(YEAR(G6),MONTH(G6),1),H6/12,0)) -> 200000 | O6: =IF(OR(G6="",H6=""),0,IF(DATE(2026,8,1)>=DATE(YEAR(G6),MONTH(G6),1),H6/12,0)) -> 200000 | P6: =IF(OR(G6="",H6=""),0,IF(DATE(2026,9,1)>=DATE(YEAR(G6),MONTH(G6),1),H6/12,0)) -> 200000 | Q6: =IF(OR(G6="",H6=""),0,IF(DATE(2026,10,1)>=DATE(YEAR(G6),MONTH(G6),1),H6/12,0)) -> 200000 | R6: =IF(OR(G6="",H6=""),0,IF(DATE(2026,11,1)>=DATE(YEAR(G6),MONTH(G6),1),H6/12,0)) -> 200000 | S6: =IF(OR(G6="",H6=""),0,IF(DATE(2026,12,1)>=DATE(YEAR(G6),MONTH(G6),1),H6/12,0)) -> 200000 | T6: =SUM(L6:S6) -> 1200000 | U6: =IF(OR(G6="",H6=""),0,IF(DATE(2027,1,1)>=DATE(YEAR(G6),MONTH(G6),1),H6/12,0)) -> 200000 | V6: =IF(OR(G6="",H6=""),0,IF(DATE(2027,2,1)>=DATE(YEAR(G6),MONTH(G6),1),H6/12,0)) -> 200000 | W6: =IF(OR(G6="",H6=""),0,IF(DATE(2027,3,1)>=DATE(YEAR(G6),MONTH(G6),1),H6/12,0)) -> 200000 | X6: =IF(OR(G6="",H6=""),0,IF(DATE(2027,4,1)>=DATE(YEAR(G6),MONTH(G6),1),H6/12,0)) -> 200000 | Y6: =IF(OR(G6="",H6=""),0,IF(DATE(2027,5,1)>=DATE(YEAR(G6),MONTH(G6),1),H6/12,0)) -> 200000 | Z6: =IF(OR(G6="",H6=""),0,IF(DATE(2027,6,1)>=DATE(YEAR(G6),MONTH(G6),1),H6/12,0)) -> 200000 | AA6: =IF(OR(G6="",H6=""),0,IF(DATE(2027,7,1)>=DATE(YEAR(G6),MONTH(G6),1),H6/12,0)) -> 200000 | AB6: =IF(OR(G6="",H6=""),0,IF(DATE(2027,8,1)>=DATE(YEAR(G6),MONTH(G6),1),H6/12,0)) -> 200000 | AC6: =IF(OR(G6="",H6=""),0,IF(DATE(2027,9,1)>=DATE(YEAR(G6),MONTH(G6),1),H6/12,0)) -> 200000 | AD6: =IF(OR(G6="",H6=""),0,IF(DATE(2027,10,1)>=DATE(YEAR(G6),MONTH(G6),1),H6/12,0)) -> 200000 | AE6: =IF(OR(G6="",H6=""),0,IF(DATE(2027,11,1)>=DATE(YEAR(G6),MONTH(G6),1),H6/12,0)) -> 200000 | AF6: =IF(OR(G6="",H6=""),0,IF(DATE(2027,12,1)>=DATE(YEAR(G6),MONTH(G6),1),H6/12,0)) -> 200000 | AG6: =SUM(U6:AF6) -> 2400000 | AH6: =T6+AG6 -> 3600000 | AI6: =IF(OR(E6="",AH6=""),"",E6*AH6) -> 720000 | AJ6: =IF('Pipeline Data Input'!M3="","",'Pipeline Data Input'!M3) -> Opp: ChampionX/DMM/WH/4000PP | Region: East
A7: 2 | B7: =IF('Pipeline Data Input'!D4="","",'Pipeline Data Input'!D4) -> NALCO Ecolab | C7: =IF('Pipeline Data Input'!E4="","",'Pipeline Data Input'!E4) -> Yazan Darwish | D7: =IF('Pipeline Data Input'!J4="","",'Pipeline Data Input'!J4) -> Contract Negotiation | E7: =IFERROR(VLOOKUP(D7,$B$211:$C$217,2,FALSE()),0) -> 0.9 | F7: =IF('Pipeline Data Input'!B4="","",IFERROR(VLOOKUP('Pipeline Data Input'!B4,'Pipeline Data Input'!$A$66:$B$80,2,FALSE()),'Pipeline Data Input'!B4)) -> Dammam 2nd Ind -Tad WH | G7: =IF('Pipeline Data Input'!K4="","",'Pipeline Data Input'!K4) -> 46174 | H7: =IF('Pipeline Data Input'!I4="",0,'Pipeline Data Input'!I4) -> 2400000 | I7: =T7 -> 1400000 | J7: =IF('Pipeline Data Input'!F4="",0,'Pipeline Data Input'!F4) -> 4000 | K7: =IF('Pipeline Data Input'!G4="",0,'Pipeline Data Input'!G4) -> 0 | L7: =IF(OR(G7="",H7=""),0,IF(DATE(2026,5,1)>=DATE(YEAR(G7),MONTH(G7),1),H7/12,0)) -> 0 | M7: =IF(OR(G7="",H7=""),0,IF(DATE(2026,6,1)>=DATE(YEAR(G7),MONTH(G7),1),H7/12,0)) -> 200000 | N7: =IF(OR(G7="",H7=""),0,IF(DATE(2026,7,1)>=DATE(YEAR(G7),MONTH(G7),1),H7/12,0)) -> 200000 | O7: =IF(OR(G7="",H7=""),0,IF(DATE(2026,8,1)>=DATE(YEAR(G7),MONTH(G7),1),H7/12,0)) -> 200000 | P7: =IF(OR(G7="",H7=""),0,IF(DATE(2026,9,1)>=DATE(YEAR(G7),MONTH(G7),1),H7/12,0)) -> 200000 | Q7: =IF(OR(G7="",H7=""),0,IF(DATE(2026,10,1)>=DATE(YEAR(G7),MONTH(G7),1),H7/12,0)) -> 200000 | R7: =IF(OR(G7="",H7=""),0,IF(DATE(2026,11,1)>=DATE(YEAR(G7),MONTH(G7),1),H7/12,0)) -> 200000 | S7: =IF(OR(G7="",H7=""),0,IF(DATE(2026,12,1)>=DATE(YEAR(G7),MONTH(G7),1),H7/12,0)) -> 200000 | T7: =SUM(L7:S7) -> 1400000 | U7: =IF(OR(G7="",H7=""),0,IF(DATE(2027,1,1)>=DATE(YEAR(G7),MONTH(G7),1),H7/12,0)) -> 200000 | V7: =IF(OR(G7="",H7=""),0,IF(DATE(2027,2,1)>=DATE(YEAR(G7),MONTH(G7),1),H7/12,0)) -> 200000 | W7: =IF(OR(G7="",H7=""),0,IF(DATE(2027,3,1)>=DATE(YEAR(G7),MONTH(G7),1),H7/12,0)) -> 200000 | X7: =IF(OR(G7="",H7=""),0,IF(DATE(2027,4,1)>=DATE(YEAR(G7),MONTH(G7),1),H7/12,0)) -> 200000 | Y7: =IF(OR(G7="",H7=""),0,IF(DATE(2027,5,1)>=DATE(YEAR(G7),MONTH(G7),1),H7/12,0)) -> 200000 | Z7: =IF(OR(G7="",H7=""),0,IF(DATE(2027,6,1)>=DATE(YEAR(G7),MONTH(G7),1),H7/12,0)) -> 200000 | AA7: =IF(OR(G7="",H7=""),0,IF(DATE(2027,7,1)>=DATE(YEAR(G7),MONTH(G7),1),H7/12,0)) -> 200000 | AB7: =IF(OR(G7="",H7=""),0,IF(DATE(2027,8,1)>=DATE(YEAR(G7),MONTH(G7),1),H7/12,0)) -> 200000 | AC7: =IF(OR(G7="",H7=""),0,IF(DATE(2027,9,1)>=DATE(YEAR(G7),MONTH(G7),1),H7/12,0)) -> 200000 | AD7: =IF(OR(G7="",H7=""),0,IF(DATE(2027,10,1)>=DATE(YEAR(G7),MONTH(G7),1),H7/12,0)) -> 200000 | AE7: =IF(OR(G7="",H7=""),0,IF(DATE(2027,11,1)>=DATE(YEAR(G7),MONTH(G7),1),H7/12,0)) -> 200000 | AF7: =IF(OR(G7="",H7=""),0,IF(DATE(2027,12,1)>=DATE(YEAR(G7),MONTH(G7),1),H7/12,0)) -> 200000 | AG7: =SUM(U7:AF7) -> 2400000 | AH7: =T7+AG7 -> 3800000 | AI7: =IF(OR(E7="",AH7=""),"",E7*AH7) -> 3420000 | AJ7: =IF('Pipeline Data Input'!M4="","",'Pipeline Data Input'!M4) -> Opp: NALCO/WH/DMM/4000PP | Region: East
A8: 3 | B8: =IF('Pipeline Data Input'!D5="","",'Pipeline Data Input'!D5) -> Synthomer ME | C8: =IF('Pipeline Data Input'!E5="","",'Pipeline Data Input'!E5) -> Yazan Darwish | D8: =IF('Pipeline Data Input'!J5="","",'Pipeline Data Input'!J5) -> Contract Negotiation | E8: =IFERROR(VLOOKUP(D8,$B$211:$C$217,2,FALSE()),0) -> 0.9 | F8: =IF('Pipeline Data Input'!B5="","",IFERROR(VLOOKUP('Pipeline Data Input'!B5,'Pipeline Data Input'!$A$66:$B$80,2,FALSE()),'Pipeline Data Input'!B5)) -> Dammam 2nd Ind -Tad WH | G8: =IF('Pipeline Data Input'!K5="","",'Pipeline Data Input'!K5) -> 46157 | H8: =IF('Pipeline Data Input'!I5="",0,'Pipeline Data Input'!I5) -> 900000 | I8: =T8 -> 600000 | J8: =IF('Pipeline Data Input'!F5="",0,'Pipeline Data Input'!F5) -> 1500 | K8: =IF('Pipeline Data Input'!G5="",0,'Pipeline Data Input'!G5) -> 0 | L8: =IF(OR(G8="",H8=""),0,IF(DATE(2026,5,1)>=DATE(YEAR(G8),MONTH(G8),1),H8/12,0)) -> 75000 | M8: =IF(OR(G8="",H8=""),0,IF(DATE(2026,6,1)>=DATE(YEAR(G8),MONTH(G8),1),H8/12,0)) -> 75000 | N8: =IF(OR(G8="",H8=""),0,IF(DATE(2026,7,1)>=DATE(YEAR(G8),MONTH(G8),1),H8/12,0)) -> 75000 | O8: =IF(OR(G8="",H8=""),0,IF(DATE(2026,8,1)>=DATE(YEAR(G8),MONTH(G8),1),H8/12,0)) -> 75000 | P8: =IF(OR(G8="",H8=""),0,IF(DATE(2026,9,1)>=DATE(YEAR(G8),MONTH(G8),1),H8/12,0)) -> 75000 | Q8: =IF(OR(G8="",H8=""),0,IF(DATE(2026,10,1)>=DATE(YEAR(G8),MONTH(G8),1),H8/12,0)) -> 75000 | R8: =IF(OR(G8="",H8=""),0,IF(DATE(2026,11,1)>=DATE(YEAR(G8),MONTH(G8),1),H8/12,0)) -> 75000 | S8: =IF(OR(G8="",H8=""),0,IF(DATE(2026,12,1)>=DATE(YEAR(G8),MONTH(G8),1),H8/12,0)) -> 75000 | T8: =SUM(L8:S8) -> 600000 | U8: =IF(OR(G8="",H8=""),0,IF(DATE(2027,1,1)>=DATE(YEAR(G8),MONTH(G8),1),H8/12,0)) -> 75000 | V8: =IF(OR(G8="",H8=""),0,IF(DATE(2027,2,1)>=DATE(YEAR(G8),MONTH(G8),1),H8/12,0)) -> 75000 | W8: =IF(OR(G8="",H8=""),0,IF(DATE(2027,3,1)>=DATE(YEAR(G8),MONTH(G8),1),H8/12,0)) -> 75000 | X8: =IF(OR(G8="",H8=""),0,IF(DATE(2027,4,1)>=DATE(YEAR(G8),MONTH(G8),1),H8/12,0)) -> 75000 | Y8: =IF(OR(G8="",H8=""),0,IF(DATE(2027,5,1)>=DATE(YEAR(G8),MONTH(G8),1),H8/12,0)) -> 75000 | Z8: =IF(OR(G8="",H8=""),0,IF(DATE(2027,6,1)>=DATE(YEAR(G8),MONTH(G8),1),H8/12,0)) -> 75000 | AA8: =IF(OR(G8="",H8=""),0,IF(DATE(2027,7,1)>=DATE(YEAR(G8),MONTH(G8),1),H8/12,0)) -> 75000 | AB8: =IF(OR(G8="",H8=""),0,IF(DATE(2027,8,1)>=DATE(YEAR(G8),MONTH(G8),1),H8/12,0)) -> 75000 | AC8: =IF(OR(G8="",H8=""),0,IF(DATE(2027,9,1)>=DATE(YEAR(G8),MONTH(G8),1),H8/12,0)) -> 75000 | AD8: =IF(OR(G8="",H8=""),0,IF(DATE(2027,10,1)>=DATE(YEAR(G8),MONTH(G8),1),H8/12,0)) -> 75000 | AE8: =IF(OR(G8="",H8=""),0,IF(DATE(2027,11,1)>=DATE(YEAR(G8),MONTH(G8),1),H8/12,0)) -> 75000 | AF8: =IF(OR(G8="",H8=""),0,IF(DATE(2027,12,1)>=DATE(YEAR(G8),MONTH(G8),1),H8/12,0)) -> 75000 | AG8: =SUM(U8:AF8) -> 900000 | AH8: =T8+AG8 -> 1500000 | AI8: =IF(OR(E8="",AH8=""),"",E8*AH8) -> 1350000 | AJ8: =IF('Pipeline Data Input'!M5="","",'Pipeline Data Input'!M5) -> Opp: Synthomer/WH/DMM/1500PP | Region: East
A9: 4 | B9: =IF('Pipeline Data Input'!D6="","",'Pipeline Data Input'!D6) -> Transworld Saudi Logistics | C9: =IF('Pipeline Data Input'!E6="","",'Pipeline Data Input'!E6) -> Yazan Darwish | D9: =IF('Pipeline Data Input'!J6="","",'Pipeline Data Input'!J6) -> Proposal Sent | E9: =IFERROR(VLOOKUP(D9,$B$211:$C$217,2,FALSE()),0) -> 0.6 | F9: =IF('Pipeline Data Input'!B6="","",IFERROR(VLOOKUP('Pipeline Data Input'!B6,'Pipeline Data Input'!$A$66:$B$80,2,FALSE()),'Pipeline Data Input'!B6)) -> Dammam 2nd Ind -Tad WH | G9: =IF('Pipeline Data Input'!K6="","",'Pipeline Data Input'!K6) -> 46143 | H9: =IF('Pipeline Data Input'!I6="",0,'Pipeline Data Input'!I6) -> 420000 | I9: =T9 -> 280000 | J9: =IF('Pipeline Data Input'!F6="",0,'Pipeline Data Input'!F6) -> 500 | K9: =IF('Pipeline Data Input'!G6="",0,'Pipeline Data Input'!G6) -> 0 | L9: =IF(OR(G9="",H9=""),0,IF(DATE(2026,5,1)>=DATE(YEAR(G9),MONTH(G9),1),H9/12,0)) -> 35000 | M9: =IF(OR(G9="",H9=""),0,IF(DATE(2026,6,1)>=DATE(YEAR(G9),MONTH(G9),1),H9/12,0)) -> 35000 | N9: =IF(OR(G9="",H9=""),0,IF(DATE(2026,7,1)>=DATE(YEAR(G9),MONTH(G9),1),H9/12,0)) -> 35000 | O9: =IF(OR(G9="",H9=""),0,IF(DATE(2026,8,1)>=DATE(YEAR(G9),MONTH(G9),1),H9/12,0)) -> 35000 | P9: =IF(OR(G9="",H9=""),0,IF(DATE(2026,9,1)>=DATE(YEAR(G9),MONTH(G9),1),H9/12,0)) -> 35000 | Q9: =IF(OR(G9="",H9=""),0,IF(DATE(2026,10,1)>=DATE(YEAR(G9),MONTH(G9),1),H9/12,0)) -> 35000 | R9: =IF(OR(G9="",H9=""),0,IF(DATE(2026,11,1)>=DATE(YEAR(G9),MONTH(G9),1),H9/12,0)) -> 35000 | S9: =IF(OR(G9="",H9=""),0,IF(DATE(2026,12,1)>=DATE(YEAR(G9),MONTH(G9),1),H9/12,0)) -> 35000 | T9: =SUM(L9:S9) -> 280000 | U9: =IF(OR(G9="",H9=""),0,IF(DATE(2027,1,1)>=DATE(YEAR(G9),MONTH(G9),1),H9/12,0)) -> 35000 | V9: =IF(OR(G9="",H9=""),0,IF(DATE(2027,2,1)>=DATE(YEAR(G9),MONTH(G9),1),H9/12,0)) -> 35000 | W9: =IF(OR(G9="",H9=""),0,IF(DATE(2027,3,1)>=DATE(YEAR(G9),MONTH(G9),1),H9/12,0)) -> 35000 | X9: =IF(OR(G9="",H9=""),0,IF(DATE(2027,4,1)>=DATE(YEAR(G9),MONTH(G9),1),H9/12,0)) -> 35000 | Y9: =IF(OR(G9="",H9=""),0,IF(DATE(2027,5,1)>=DATE(YEAR(G9),MONTH(G9),1),H9/12,0)) -> 35000 | Z9: =IF(OR(G9="",H9=""),0,IF(DATE(2027,6,1)>=DATE(YEAR(G9),MONTH(G9),1),H9/12,0)) -> 35000 | AA9: =IF(OR(G9="",H9=""),0,IF(DATE(2027,7,1)>=DATE(YEAR(G9),MONTH(G9),1),H9/12,0)) -> 35000 | AB9: =IF(OR(G9="",H9=""),0,IF(DATE(2027,8,1)>=DATE(YEAR(G9),MONTH(G9),1),H9/12,0)) -> 35000 | AC9: =IF(OR(G9="",H9=""),0,IF(DATE(2027,9,1)>=DATE(YEAR(G9),MONTH(G9),1),H9/12,0)) -> 35000 | AD9: =IF(OR(G9="",H9=""),0,IF(DATE(2027,10,1)>=DATE(YEAR(G9),MONTH(G9),1),H9/12,0)) -> 35000 | AE9: =IF(OR(G9="",H9=""),0,IF(DATE(2027,11,1)>=DATE(YEAR(G9),MONTH(G9),1),H9/12,0)) -> 35000 | AF9: =IF(OR(G9="",H9=""),0,IF(DATE(2027,12,1)>=DATE(YEAR(G9),MONTH(G9),1),H9/12,0)) -> 35000 | AG9: =SUM(U9:AF9) -> 420000 | AH9: =T9+AG9 -> 700000 | AI9: =IF(OR(E9="",AH9=""),"",E9*AH9) -> 420000 | AJ9: =IF('Pipeline Data Input'!M6="","",'Pipeline Data Input'!M6) -> Opp: Transworld/DMM/WH/500PP | Region: East
A10: 5 | B10: =IF('Pipeline Data Input'!D7="","",'Pipeline Data Input'!D7) -> Schmidt | C10: =IF('Pipeline Data Input'!E7="","",'Pipeline Data Input'!E7) -> Yazan Darwish | D10: =IF('Pipeline Data Input'!J7="","",'Pipeline Data Input'!J7) -> Proposal Sent | E10: =IFERROR(VLOOKUP(D10,$B$211:$C$217,2,FALSE()),0) -> 0.6 | F10: =IF('Pipeline Data Input'!B7="","",IFERROR(VLOOKUP('Pipeline Data Input'!B7,'Pipeline Data Input'!$A$66:$B$80,2,FALSE()),'Pipeline Data Input'!B7)) -> Dammam 2nd Ind -Tad WH | G10: =IF('Pipeline Data Input'!K7="","",'Pipeline Data Input'!K7) -> 46143 | H10: =IF('Pipeline Data Input'!I7="",0,'Pipeline Data Input'!I7) -> 264000 | I10: =T10 -> 176000 | J10: =IF('Pipeline Data Input'!F7="",0,'Pipeline Data Input'!F7) -> 400 | K10: =IF('Pipeline Data Input'!G7="",0,'Pipeline Data Input'!G7) -> 0 | L10: =IF(OR(G10="",H10=""),0,IF(DATE(2026,5,1)>=DATE(YEAR(G10),MONTH(G10),1),H10/12,0)) -> 22000 | M10: =IF(OR(G10="",H10=""),0,IF(DATE(2026,6,1)>=DATE(YEAR(G10),MONTH(G10),1),H10/12,0)) -> 22000 | N10: =IF(OR(G10="",H10=""),0,IF(DATE(2026,7,1)>=DATE(YEAR(G10),MONTH(G10),1),H10/12,0)) -> 22000 | O10: =IF(OR(G10="",H10=""),0,IF(DATE(2026,8,1)>=DATE(YEAR(G10),MONTH(G10),1),H10/12,0)) -> 22000 | P10: =IF(OR(G10="",H10=""),0,IF(DATE(2026,9,1)>=DATE(YEAR(G10),MONTH(G10),1),H10/12,0)) -> 22000 | Q10: =IF(OR(G10="",H10=""),0,IF(DATE(2026,10,1)>=DATE(YEAR(G10),MONTH(G10),1),H10/12,0)) -> 22000 | R10: =IF(OR(G10="",H10=""),0,IF(DATE(2026,11,1)>=DATE(YEAR(G10),MONTH(G10),1),H10/12,0)) -> 22000 | S10: =IF(OR(G10="",H10=""),0,IF(DATE(2026,12,1)>=DATE(YEAR(G10),MONTH(G10),1),H10/12,0)) -> 22000 | T10: =SUM(L10:S10) -> 176000 | U10: =IF(OR(G10="",H10=""),0,IF(DATE(2027,1,1)>=DATE(YEAR(G10),MONTH(G10),1),H10/12,0)) -> 22000 | V10: =IF(OR(G10="",H10=""),0,IF(DATE(2027,2,1)>=DATE(YEAR(G10),MONTH(G10),1),H10/12,0)) -> 22000 | W10: =IF(OR(G10="",H10=""),0,IF(DATE(2027,3,1)>=DATE(YEAR(G10),MONTH(G10),1),H10/12,0)) -> 22000 | X10: =IF(OR(G10="",H10=""),0,IF(DATE(2027,4,1)>=DATE(YEAR(G10),MONTH(G10),1),H10/12,0)) -> 22000 | Y10: =IF(OR(G10="",H10=""),0,IF(DATE(2027,5,1)>=DATE(YEAR(G10),MONTH(G10),1),H10/12,0)) -> 22000 | Z10: =IF(OR(G10="",H10=""),0,IF(DATE(2027,6,1)>=DATE(YEAR(G10),MONTH(G10),1),H10/12,0)) -> 22000 | AA10: =IF(OR(G10="",H10=""),0,IF(DATE(2027,7,1)>=DATE(YEAR(G10),MONTH(G10),1),H10/12,0)) -> 22000 | AB10: =IF(OR(G10="",H10=""),0,IF(DATE(2027,8,1)>=DATE(YEAR(G10),MONTH(G10),1),H10/12,0)) -> 22000 | AC10: =IF(OR(G10="",H10=""),0,IF(DATE(2027,9,1)>=DATE(YEAR(G10),MONTH(G10),1),H10/12,0)) -> 22000 | AD10: =IF(OR(G10="",H10=""),0,IF(DATE(2027,10,1)>=DATE(YEAR(G10),MONTH(G10),1),H10/12,0)) -> 22000 | AE10: =IF(OR(G10="",H10=""),0,IF(DATE(2027,11,1)>=DATE(YEAR(G10),MONTH(G10),1),H10/12,0)) -> 22000 | AF10: =IF(OR(G10="",H10=""),0,IF(DATE(2027,12,1)>=DATE(YEAR(G10),MONTH(G10),1),H10/12,0)) -> 22000 | AG10: =SUM(U10:AF10) -> 264000 | AH10: =T10+AG10 -> 440000 | AI10: =IF(OR(E10="",AH10=""),"",E10*AH10) -> 264000 | AJ10: =IF('Pipeline Data Input'!M7="","",'Pipeline Data Input'!M7) -> Opp: Schmidt/WH/DMM2/400PP | Region: East
A11: 6 | B11: =IF('Pipeline Data Input'!D8="","",'Pipeline Data Input'!D8) -> Zaghami | C11: =IF('Pipeline Data Input'!E8="","",'Pipeline Data Input'!E8) -> Yazan Darwish | D11: =IF('Pipeline Data Input'!J8="","",'Pipeline Data Input'!J8) -> Proposal Sent | E11: =IFERROR(VLOOKUP(D11,$B$211:$C$217,2,FALSE()),0) -> 0.6 | F11: =IF('Pipeline Data Input'!B8="","",IFERROR(VLOOKUP('Pipeline Data Input'!B8,'Pipeline Data Input'!$A$66:$B$80,2,FALSE()),'Pipeline Data Input'!B8)) -> Dammam 2nd Ind -Tad WH | G11: =IF('Pipeline Data Input'!K8="","",'Pipeline Data Input'!K8) -> 46235 | H11: =IF('Pipeline Data Input'!I8="",0,'Pipeline Data Input'!I8) -> 210000 | I11: =T11 -> 87500 | J11: =IF('Pipeline Data Input'!F8="",0,'Pipeline Data Input'!F8) -> 250 | K11: =IF('Pipeline Data Input'!G8="",0,'Pipeline Data Input'!G8) -> 0 | L11: =IF(OR(G11="",H11=""),0,IF(DATE(2026,5,1)>=DATE(YEAR(G11),MONTH(G11),1),H11/12,0)) -> 0 | M11: =IF(OR(G11="",H11=""),0,IF(DATE(2026,6,1)>=DATE(YEAR(G11),MONTH(G11),1),H11/12,0)) -> 0 | N11: =IF(OR(G11="",H11=""),0,IF(DATE(2026,7,1)>=DATE(YEAR(G11),MONTH(G11),1),H11/12,0)) -> 0 | O11: =IF(OR(G11="",H11=""),0,IF(DATE(2026,8,1)>=DATE(YEAR(G11),MONTH(G11),1),H11/12,0)) -> 17500 | P11: =IF(OR(G11="",H11=""),0,IF(DATE(2026,9,1)>=DATE(YEAR(G11),MONTH(G11),1),H11/12,0)) -> 17500 | Q11: =IF(OR(G11="",H11=""),0,IF(DATE(2026,10,1)>=DATE(YEAR(G11),MONTH(G11),1),H11/12,0)) -> 17500 | R11: =IF(OR(G11="",H11=""),0,IF(DATE(2026,11,1)>=DATE(YEAR(G11),MONTH(G11),1),H11/12,0)) -> 17500 | S11: =IF(OR(G11="",H11=""),0,IF(DATE(2026,12,1)>=DATE(YEAR(G11),MONTH(G11),1),H11/12,0)) -> 17500 | T11: =SUM(L11:S11) -> 87500 | U11: =IF(OR(G11="",H11=""),0,IF(DATE(2027,1,1)>=DATE(YEAR(G11),MONTH(G11),1),H11/12,0)) -> 17500 | V11: =IF(OR(G11="",H11=""),0,IF(DATE(2027,2,1)>=DATE(YEAR(G11),MONTH(G11),1),H11/12,0)) -> 17500 | W11: =IF(OR(G11="",H11=""),0,IF(DATE(2027,3,1)>=DATE(YEAR(G11),MONTH(G11),1),H11/12,0)) -> 17500 | X11: =IF(OR(G11="",H11=""),0,IF(DATE(2027,4,1)>=DATE(YEAR(G11),MONTH(G11),1),H11/12,0)) -> 17500 | Y11: =IF(OR(G11="",H11=""),0,IF(DATE(2027,5,1)>=DATE(YEAR(G11),MONTH(G11),1),H11/12,0)) -> 17500 | Z11: =IF(OR(G11="",H11=""),0,IF(DATE(2027,6,1)>=DATE(YEAR(G11),MONTH(G11),1),H11/12,0)) -> 17500 | AA11: =IF(OR(G11="",H11=""),0,IF(DATE(2027,7,1)>=DATE(YEAR(G11),MONTH(G11),1),H11/12,0)) -> 17500 | AB11: =IF(OR(G11="",H11=""),0,IF(DATE(2027,8,1)>=DATE(YEAR(G11),MONTH(G11),1),H11/12,0)) -> 17500 | AC11: =IF(OR(G11="",H11=""),0,IF(DATE(2027,9,1)>=DATE(YEAR(G11),MONTH(G11),1),H11/12,0)) -> 17500 | AD11: =IF(OR(G11="",H11=""),0,IF(DATE(2027,10,1)>=DATE(YEAR(G11),MONTH(G11),1),H11/12,0)) -> 17500 | AE11: =IF(OR(G11="",H11=""),0,IF(DATE(2027,11,1)>=DATE(YEAR(G11),MONTH(G11),1),H11/12,0)) -> 17500 | AF11: =IF(OR(G11="",H11=""),0,IF(DATE(2027,12,1)>=DATE(YEAR(G11),MONTH(G11),1),H11/12,0)) -> 17500 | AG11: =SUM(U11:AF11) -> 210000 | AH11: =T11+AG11 -> 297500 | AI11: =IF(OR(E11="",AH11=""),"",E11*AH11) -> 178500 | AJ11: =IF('Pipeline Data Input'!M8="","",'Pipeline Data Input'!M8) -> Opp: Zaghami/WH/DMM/250PP | Region: East
A12: 7 | B12: =IF('Pipeline Data Input'!D9="","",'Pipeline Data Input'!D9) -> Transworld Saudi Logistics | C12: =IF('Pipeline Data Input'!E9="","",'Pipeline Data Input'!E9) -> Yazan Darwish | D12: =IF('Pipeline Data Input'!J9="","",'Pipeline Data Input'!J9) -> Proposal Sent | E12: =IFERROR(VLOOKUP(D12,$B$211:$C$217,2,FALSE()),0) -> 0.6 | F12: =IF('Pipeline Data Input'!B9="","",IFERROR(VLOOKUP('Pipeline Data Input'!B9,'Pipeline Data Input'!$A$66:$B$80,2,FALSE()),'Pipeline Data Input'!B9)) -> Dammam 2nd Ind -Tad WH | G12: =IF('Pipeline Data Input'!K9="","",'Pipeline Data Input'!K9) -> 46174 | H12: =IF('Pipeline Data Input'!I9="",0,'Pipeline Data Input'!I9) -> 162500 | I12: =T12 -> 94791.667 | J12: =IF('Pipeline Data Input'!F9="",0,'Pipeline Data Input'!F9) -> 250 | K12: =IF('Pipeline Data Input'!G9="",0,'Pipeline Data Input'!G9) -> 0 | L12: =IF(OR(G12="",H12=""),0,IF(DATE(2026,5,1)>=DATE(YEAR(G12),MONTH(G12),1),H12/12,0)) -> 0 | M12: =IF(OR(G12="",H12=""),0,IF(DATE(2026,6,1)>=DATE(YEAR(G12),MONTH(G12),1),H12/12,0)) -> 13541.667 | N12: =IF(OR(G12="",H12=""),0,IF(DATE(2026,7,1)>=DATE(YEAR(G12),MONTH(G12),1),H12/12,0)) -> 13541.667 | O12: =IF(OR(G12="",H12=""),0,IF(DATE(2026,8,1)>=DATE(YEAR(G12),MONTH(G12),1),H12/12,0)) -> 13541.667 | P12: =IF(OR(G12="",H12=""),0,IF(DATE(2026,9,1)>=DATE(YEAR(G12),MONTH(G12),1),H12/12,0)) -> 13541.667 | Q12: =IF(OR(G12="",H12=""),0,IF(DATE(2026,10,1)>=DATE(YEAR(G12),MONTH(G12),1),H12/12,0)) -> 13541.667 | R12: =IF(OR(G12="",H12=""),0,IF(DATE(2026,11,1)>=DATE(YEAR(G12),MONTH(G12),1),H12/12,0)) -> 13541.667 | S12: =IF(OR(G12="",H12=""),0,IF(DATE(2026,12,1)>=DATE(YEAR(G12),MONTH(G12),1),H12/12,0)) -> 13541.667 | T12: =SUM(L12:S12) -> 94791.667 | U12: =IF(OR(G12="",H12=""),0,IF(DATE(2027,1,1)>=DATE(YEAR(G12),MONTH(G12),1),H12/12,0)) -> 13541.667 | V12: =IF(OR(G12="",H12=""),0,IF(DATE(2027,2,1)>=DATE(YEAR(G12),MONTH(G12),1),H12/12,0)) -> 13541.667 | W12: =IF(OR(G12="",H12=""),0,IF(DATE(2027,3,1)>=DATE(YEAR(G12),MONTH(G12),1),H12/12,0)) -> 13541.667 | X12: =IF(OR(G12="",H12=""),0,IF(DATE(2027,4,1)>=DATE(YEAR(G12),MONTH(G12),1),H12/12,0)) -> 13541.667 | Y12: =IF(OR(G12="",H12=""),0,IF(DATE(2027,5,1)>=DATE(YEAR(G12),MONTH(G12),1),H12/12,0)) -> 13541.667 | Z12: =IF(OR(G12="",H12=""),0,IF(DATE(2027,6,1)>=DATE(YEAR(G12),MONTH(G12),1),H12/12,0)) -> 13541.667 | AA12: =IF(OR(G12="",H12=""),0,IF(DATE(2027,7,1)>=DATE(YEAR(G12),MONTH(G12),1),H12/12,0)) -> 13541.667 | AB12: =IF(OR(G12="",H12=""),0,IF(DATE(2027,8,1)>=DATE(YEAR(G12),MONTH(G12),1),H12/12,0)) -> 13541.667 | AC12: =IF(OR(G12="",H12=""),0,IF(DATE(2027,9,1)>=DATE(YEAR(G12),MONTH(G12),1),H12/12,0)) -> 13541.667 | AD12: =IF(OR(G12="",H12=""),0,IF(DATE(2027,10,1)>=DATE(YEAR(G12),MONTH(G12),1),H12/12,0)) -> 13541.667 | AE12: =IF(OR(G12="",H12=""),0,IF(DATE(2027,11,1)>=DATE(YEAR(G12),MONTH(G12),1),H12/12,0)) -> 13541.667 | AF12: =IF(OR(G12="",H12=""),0,IF(DATE(2027,12,1)>=DATE(YEAR(G12),MONTH(G12),1),H12/12,0)) -> 13541.667 | AG12: =SUM(U12:AF12) -> 162500 | AH12: =T12+AG12 -> 257291.67 | AI12: =IF(OR(E12="",AH12=""),"",E12*AH12) -> 154375 | AJ12: =IF('Pipeline Data Input'!M9="","",'Pipeline Data Input'!M9) -> ⚠ Source Exp CY (113,750) ≠ ACV/12 implied (94,792) | Opp: Transworld/DMM/WH/250PP | Region: East
A13: 8 | B13: =IF('Pipeline Data Input'!D10="","",'Pipeline Data Input'!D10) -> i-Energy | C13: =IF('Pipeline Data Input'!E10="","",'Pipeline Data Input'!E10) -> Yazan Darwish | D13: =IF('Pipeline Data Input'!J10="","",'Pipeline Data Input'!J10) -> Proposal Sent | E13: =IFERROR(VLOOKUP(D13,$B$211:$C$217,2,FALSE()),0) -> 0.6 | F13: =IF('Pipeline Data Input'!B10="","",IFERROR(VLOOKUP('Pipeline Data Input'!B10,'Pipeline Data Input'!$A$66:$B$80,2,FALSE()),'Pipeline Data Input'!B10)) -> Dammam 2nd Ind -Tad WH | G13: =IF('Pipeline Data Input'!K10="","",'Pipeline Data Input'!K10) -> 46143 | H13: =IF('Pipeline Data Input'!I10="",0,'Pipeline Data Input'!I10) -> 150000 | I13: =T13 -> 100000 | J13: =IF('Pipeline Data Input'!F10="",0,'Pipeline Data Input'!F10) -> 250 | K13: =IF('Pipeline Data Input'!G10="",0,'Pipeline Data Input'!G10) -> 0 | L13: =IF(OR(G13="",H13=""),0,IF(DATE(2026,5,1)>=DATE(YEAR(G13),MONTH(G13),1),H13/12,0)) -> 12500 | M13: =IF(OR(G13="",H13=""),0,IF(DATE(2026,6,1)>=DATE(YEAR(G13),MONTH(G13),1),H13/12,0)) -> 12500 | N13: =IF(OR(G13="",H13=""),0,IF(DATE(2026,7,1)>=DATE(YEAR(G13),MONTH(G13),1),H13/12,0)) -> 12500 | O13: =IF(OR(G13="",H13=""),0,IF(DATE(2026,8,1)>=DATE(YEAR(G13),MONTH(G13),1),H13/12,0)) -> 12500 | P13: =IF(OR(G13="",H13=""),0,IF(DATE(2026,9,1)>=DATE(YEAR(G13),MONTH(G13),1),H13/12,0)) -> 12500 | Q13: =IF(OR(G13="",H13=""),0,IF(DATE(2026,10,1)>=DATE(YEAR(G13),MONTH(G13),1),H13/12,0)) -> 12500 | R13: =IF(OR(G13="",H13=""),0,IF(DATE(2026,11,1)>=DATE(YEAR(G13),MONTH(G13),1),H13/12,0)) -> 12500 | S13: =IF(OR(G13="",H13=""),0,IF(DATE(2026,12,1)>=DATE(YEAR(G13),MONTH(G13),1),H13/12,0)) -> 12500 | T13: =SUM(L13:S13) -> 100000 | U13: =IF(OR(G13="",H13=""),0,IF(DATE(2027,1,1)>=DATE(YEAR(G13),MONTH(G13),1),H13/12,0)) -> 12500 | V13: =IF(OR(G13="",H13=""),0,IF(DATE(2027,2,1)>=DATE(YEAR(G13),MONTH(G13),1),H13/12,0)) -> 12500 | W13: =IF(OR(G13="",H13=""),0,IF(DATE(2027,3,1)>=DATE(YEAR(G13),MONTH(G13),1),H13/12,0)) -> 12500 | X13: =IF(OR(G13="",H13=""),0,IF(DATE(2027,4,1)>=DATE(YEAR(G13),MONTH(G13),1),H13/12,0)) -> 12500 | Y13: =IF(OR(G13="",H13=""),0,IF(DATE(2027,5,1)>=DATE(YEAR(G13),MONTH(G13),1),H13/12,0)) -> 12500 | Z13: =IF(OR(G13="",H13=""),0,IF(DATE(2027,6,1)>=DATE(YEAR(G13),MONTH(G13),1),H13/12,0)) -> 12500 | AA13: =IF(OR(G13="",H13=""),0,IF(DATE(2027,7,1)>=DATE(YEAR(G13),MONTH(G13),1),H13/12,0)) -> 12500 | AB13: =IF(OR(G13="",H13=""),0,IF(DATE(2027,8,1)>=DATE(YEAR(G13),MONTH(G13),1),H13/12,0)) -> 12500 | AC13: =IF(OR(G13="",H13=""),0,IF(DATE(2027,9,1)>=DATE(YEAR(G13),MONTH(G13),1),H13/12,0)) -> 12500 | AD13: =IF(OR(G13="",H13=""),0,IF(DATE(2027,10,1)>=DATE(YEAR(G13),MONTH(G13),1),H13/12,0)) -> 12500 | AE13: =IF(OR(G13="",H13=""),0,IF(DATE(2027,11,1)>=DATE(YEAR(G13),MONTH(G13),1),H13/12,0)) -> 12500 | AF13: =IF(OR(G13="",H13=""),0,IF(DATE(2027,12,1)>=DATE(YEAR(G13),MONTH(G13),1),H13/12,0)) -> 12500 | AG13: =SUM(U13:AF13) -> 150000 | AH13: =T13+AG13 -> 250000 | AI13: =IF(OR(E13="",AH13=""),"",E13*AH13) -> 150000 | AJ13: =IF('Pipeline Data Input'!M10="","",'Pipeline Data Input'!M10) -> Opp: iEnergy/WH/DMM2/250PP | Region: East
A14: 9 | B14: =IF('Pipeline Data Input'!D11="","",'Pipeline Data Input'!D11) -> FMS Group | C14: =IF('Pipeline Data Input'!E11="","",'Pipeline Data Input'!E11) -> Yazan Darwish | D14: =IF('Pipeline Data Input'!J11="","",'Pipeline Data Input'!J11) -> Proposal Sent | E14: =IFERROR(VLOOKUP(D14,$B$211:$C$217,2,FALSE()),0) -> 0.6 | F14: =IF('Pipeline Data Input'!B11="","",IFERROR(VLOOKUP('Pipeline Data Input'!B11,'Pipeline Data Input'!$A$66:$B$80,2,FALSE()),'Pipeline Data Input'!B11)) -> Dammam 2nd Ind -Tad WH | G14: =IF('Pipeline Data Input'!K11="","",'Pipeline Data Input'!K11) -> 46174 | H14: =IF('Pipeline Data Input'!I11="",0,'Pipeline Data Input'!I11) -> 50000 | I14: =T14 -> 29166.667 | J14: =IF('Pipeline Data Input'!F11="",0,'Pipeline Data Input'!F11) -> 100 | K14: =IF('Pipeline Data Input'!G11="",0,'Pipeline Data Input'!G11) -> 0 | L14: =IF(OR(G14="",H14=""),0,IF(DATE(2026,5,1)>=DATE(YEAR(G14),MONTH(G14),1),H14/12,0)) -> 0 | M14: =IF(OR(G14="",H14=""),0,IF(DATE(2026,6,1)>=DATE(YEAR(G14),MONTH(G14),1),H14/12,0)) -> 4166.6667 | N14: =IF(OR(G14="",H14=""),0,IF(DATE(2026,7,1)>=DATE(YEAR(G14),MONTH(G14),1),H14/12,0)) -> 4166.6667 | O14: =IF(OR(G14="",H14=""),0,IF(DATE(2026,8,1)>=DATE(YEAR(G14),MONTH(G14),1),H14/12,0)) -> 4166.6667 | P14: =IF(OR(G14="",H14=""),0,IF(DATE(2026,9,1)>=DATE(YEAR(G14),MONTH(G14),1),H14/12,0)) -> 4166.6667 | Q14: =IF(OR(G14="",H14=""),0,IF(DATE(2026,10,1)>=DATE(YEAR(G14),MONTH(G14),1),H14/12,0)) -> 4166.6667 | R14: =IF(OR(G14="",H14=""),0,IF(DATE(2026,11,1)>=DATE(YEAR(G14),MONTH(G14),1),H14/12,0)) -> 4166.6667 | S14: =IF(OR(G14="",H14=""),0,IF(DATE(2026,12,1)>=DATE(YEAR(G14),MONTH(G14),1),H14/12,0)) -> 4166.6667 | T14: =SUM(L14:S14) -> 29166.667 | U14: =IF(OR(G14="",H14=""),0,IF(DATE(2027,1,1)>=DATE(YEAR(G14),MONTH(G14),1),H14/12,0)) -> 4166.6667 | V14: =IF(OR(G14="",H14=""),0,IF(DATE(2027,2,1)>=DATE(YEAR(G14),MONTH(G14),1),H14/12,0)) -> 4166.6667 | W14: =IF(OR(G14="",H14=""),0,IF(DATE(2027,3,1)>=DATE(YEAR(G14),MONTH(G14),1),H14/12,0)) -> 4166.6667 | X14: =IF(OR(G14="",H14=""),0,IF(DATE(2027,4,1)>=DATE(YEAR(G14),MONTH(G14),1),H14/12,0)) -> 4166.6667 | Y14: =IF(OR(G14="",H14=""),0,IF(DATE(2027,5,1)>=DATE(YEAR(G14),MONTH(G14),1),H14/12,0)) -> 4166.6667 | Z14: =IF(OR(G14="",H14=""),0,IF(DATE(2027,6,1)>=DATE(YEAR(G14),MONTH(G14),1),H14/12,0)) -> 4166.6667 | AA14: =IF(OR(G14="",H14=""),0,IF(DATE(2027,7,1)>=DATE(YEAR(G14),MONTH(G14),1),H14/12,0)) -> 4166.6667 | AB14: =IF(OR(G14="",H14=""),0,IF(DATE(2027,8,1)>=DATE(YEAR(G14),MONTH(G14),1),H14/12,0)) -> 4166.6667 | AC14: =IF(OR(G14="",H14=""),0,IF(DATE(2027,9,1)>=DATE(YEAR(G14),MONTH(G14),1),H14/12,0)) -> 4166.6667 | AD14: =IF(OR(G14="",H14=""),0,IF(DATE(2027,10,1)>=DATE(YEAR(G14),MONTH(G14),1),H14/12,0)) -> 4166.6667 | AE14: =IF(OR(G14="",H14=""),0,IF(DATE(2027,11,1)>=DATE(YEAR(G14),MONTH(G14),1),H14/12,0)) -> 4166.6667 | AF14: =IF(OR(G14="",H14=""),0,IF(DATE(2027,12,1)>=DATE(YEAR(G14),MONTH(G14),1),H14/12,0)) -> 4166.6667 | AG14: =SUM(U14:AF14) -> 50000 | AH14: =T14+AG14 -> 79166.667 | AI14: =IF(OR(E14="",AH14=""),"",E14*AH14) -> 47500 | AJ14: =IF('Pipeline Data Input'!M11="","",'Pipeline Data Input'!M11) -> ⚠ Source Exp CY (35,000) ≠ ACV/12 implied (29,167) | Opp: FMS/DMM/WH/100PP | Region: East
A15: 10 | B15: =IF('Pipeline Data Input'!D12="","",'Pipeline Data Input'!D12) -> El Ajou Group | C15: =IF('Pipeline Data Input'!E12="","",'Pipeline Data Input'!E12) -> Yazan Darwish | D15: =IF('Pipeline Data Input'!J12="","",'Pipeline Data Input'!J12) -> Proposal Sent | E15: =IFERROR(VLOOKUP(D15,$B$211:$C$217,2,FALSE()),0) -> 0.6 | F15: =IF('Pipeline Data Input'!B12="","",IFERROR(VLOOKUP('Pipeline Data Input'!B12,'Pipeline Data Input'!$A$66:$B$80,2,FALSE()),'Pipeline Data Input'!B12)) -> Dammam 2nd Ind -Tad WH | G15: =IF('Pipeline Data Input'!K12="","",'Pipeline Data Input'!K12) -> 46204 | H15: =IF('Pipeline Data Input'!I12="",0,'Pipeline Data Input'!I12) -> 78000 | I15: =T15 -> 39000 | J15: =IF('Pipeline Data Input'!F12="",0,'Pipeline Data Input'!F12) -> 100 | K15: =IF('Pipeline Data Input'!G12="",0,'Pipeline Data Input'!G12) -> 0 | L15: =IF(OR(G15="",H15=""),0,IF(DATE(2026,5,1)>=DATE(YEAR(G15),MONTH(G15),1),H15/12,0)) -> 0 | M15: =IF(OR(G15="",H15=""),0,IF(DATE(2026,6,1)>=DATE(YEAR(G15),MONTH(G15),1),H15/12,0)) -> 0 | N15: =IF(OR(G15="",H15=""),0,IF(DATE(2026,7,1)>=DATE(YEAR(G15),MONTH(G15),1),H15/12,0)) -> 6500 | O15: =IF(OR(G15="",H15=""),0,IF(DATE(2026,8,1)>=DATE(YEAR(G15),MONTH(G15),1),H15/12,0)) -> 6500 | P15: =IF(OR(G15="",H15=""),0,IF(DATE(2026,9,1)>=DATE(YEAR(G15),MONTH(G15),1),H15/12,0)) -> 6500 | Q15: =IF(OR(G15="",H15=""),0,IF(DATE(2026,10,1)>=DATE(YEAR(G15),MONTH(G15),1),H15/12,0)) -> 6500 | R15: =IF(OR(G15="",H15=""),0,IF(DATE(2026,11,1)>=DATE(YEAR(G15),MONTH(G15),1),H15/12,0)) -> 6500 | S15: =IF(OR(G15="",H15=""),0,IF(DATE(2026,12,1)>=DATE(YEAR(G15),MONTH(G15),1),H15/12,0)) -> 6500 | T15: =SUM(L15:S15) -> 39000 | U15: =IF(OR(G15="",H15=""),0,IF(DATE(2027,1,1)>=DATE(YEAR(G15),MONTH(G15),1),H15/12,0)) -> 6500 | V15: =IF(OR(G15="",H15=""),0,IF(DATE(2027,2,1)>=DATE(YEAR(G15),MONTH(G15),1),H15/12,0)) -> 6500 | W15: =IF(OR(G15="",H15=""),0,IF(DATE(2027,3,1)>=DATE(YEAR(G15),MONTH(G15),1),H15/12,0)) -> 6500 | X15: =IF(OR(G15="",H15=""),0,IF(DATE(2027,4,1)>=DATE(YEAR(G15),MONTH(G15),1),H15/12,0)) -> 6500 | Y15: =IF(OR(G15="",H15=""),0,IF(DATE(2027,5,1)>=DATE(YEAR(G15),MONTH(G15),1),H15/12,0)) -> 6500 | Z15: =IF(OR(G15="",H15=""),0,IF(DATE(2027,6,1)>=DATE(YEAR(G15),MONTH(G15),1),H15/12,0)) -> 6500 | AA15: =IF(OR(G15="",H15=""),0,IF(DATE(2027,7,1)>=DATE(YEAR(G15),MONTH(G15),1),H15/12,0)) -> 6500 | AB15: =IF(OR(G15="",H15=""),0,IF(DATE(2027,8,1)>=DATE(YEAR(G15),MONTH(G15),1),H15/12,0)) -> 6500 | AC15: =IF(OR(G15="",H15=""),0,IF(DATE(2027,9,1)>=DATE(YEAR(G15),MONTH(G15),1),H15/12,0)) -> 6500 | AD15: =IF(OR(G15="",H15=""),0,IF(DATE(2027,10,1)>=DATE(YEAR(G15),MONTH(G15),1),H15/12,0)) -> 6500 | AE15: =IF(OR(G15="",H15=""),0,IF(DATE(2027,11,1)>=DATE(YEAR(G15),MONTH(G15),1),H15/12,0)) -> 6500 | AF15: =IF(OR(G15="",H15=""),0,IF(DATE(2027,12,1)>=DATE(YEAR(G15),MONTH(G15),1),H15/12,0)) -> 6500 | AG15: =SUM(U15:AF15) -> 78000 | AH15: =T15+AG15 -> 117000 | AI15: =IF(OR(E15="",AH15=""),"",E15*AH15) -> 70200 | AJ15: =IF('Pipeline Data Input'!M12="","",'Pipeline Data Input'!M12) -> Opp: El Ajou Group/WH/DAMM2nd/100PP | Region: East
A16: 11 | B16: =IF('Pipeline Data Input'!D13="","",'Pipeline Data Input'!D13) -> JAS | C16: =IF('Pipeline Data Input'!E13="","",'Pipeline Data Input'!E13) -> Yazan Darwish | D16: =IF('Pipeline Data Input'!J13="","",'Pipeline Data Input'!J13) -> Shortlisted | E16: =IFERROR(VLOOKUP(D16,$B$211:$C$217,2,FALSE()),0) -> 0.75 | F16: =IF('Pipeline Data Input'!B13="","",IFERROR(VLOOKUP('Pipeline Data Input'!B13,'Pipeline Data Input'!$A$66:$B$80,2,FALSE()),'Pipeline Data Input'!B13)) -> Jubail 1 | G16: =IF('Pipeline Data Input'!K13="","",'Pipeline Data Input'!K13) -> 46174 | H16: =IF('Pipeline Data Input'!I13="",0,'Pipeline Data Input'!I13) -> 924000 | I16: =T16 -> 539000 | J16: =IF('Pipeline Data Input'!F13="",0,'Pipeline Data Input'!F13) -> 1400 | K16: =IF('Pipeline Data Input'!G13="",0,'Pipeline Data Input'!G13) -> 0 | L16: =IF(OR(G16="",H16=""),0,IF(DATE(2026,5,1)>=DATE(YEAR(G16),MONTH(G16),1),H16/12,0)) -> 0 | M16: =IF(OR(G16="",H16=""),0,IF(DATE(2026,6,1)>=DATE(YEAR(G16),MONTH(G16),1),H16/12,0)) -> 77000 | N16: =IF(OR(G16="",H16=""),0,IF(DATE(2026,7,1)>=DATE(YEAR(G16),MONTH(G16),1),H16/12,0)) -> 77000 | O16: =IF(OR(G16="",H16=""),0,IF(DATE(2026,8,1)>=DATE(YEAR(G16),MONTH(G16),1),H16/12,0)) -> 77000 | P16: =IF(OR(G16="",H16=""),0,IF(DATE(2026,9,1)>=DATE(YEAR(G16),MONTH(G16),1),H16/12,0)) -> 77000 | Q16: =IF(OR(G16="",H16=""),0,IF(DATE(2026,10,1)>=DATE(YEAR(G16),MONTH(G16),1),H16/12,0)) -> 77000 | R16: =IF(OR(G16="",H16=""),0,IF(DATE(2026,11,1)>=DATE(YEAR(G16),MONTH(G16),1),H16/12,0)) -> 77000 | S16: =IF(OR(G16="",H16=""),0,IF(DATE(2026,12,1)>=DATE(YEAR(G16),MONTH(G16),1),H16/12,0)) -> 77000 | T16: =SUM(L16:S16) -> 539000 | U16: =IF(OR(G16="",H16=""),0,IF(DATE(2027,1,1)>=DATE(YEAR(G16),MONTH(G16),1),H16/12,0)) -> 77000 | V16: =IF(OR(G16="",H16=""),0,IF(DATE(2027,2,1)>=DATE(YEAR(G16),MONTH(G16),1),H16/12,0)) -> 77000 | W16: =IF(OR(G16="",H16=""),0,IF(DATE(2027,3,1)>=DATE(YEAR(G16),MONTH(G16),1),H16/12,0)) -> 77000 | X16: =IF(OR(G16="",H16=""),0,IF(DATE(2027,4,1)>=DATE(YEAR(G16),MONTH(G16),1),H16/12,0)) -> 77000 | Y16: =IF(OR(G16="",H16=""),0,IF(DATE(2027,5,1)>=DATE(YEAR(G16),MONTH(G16),1),H16/12,0)) -> 77000 | Z16: =IF(OR(G16="",H16=""),0,IF(DATE(2027,6,1)>=DATE(YEAR(G16),MONTH(G16),1),H16/12,0)) -> 77000 | AA16: =IF(OR(G16="",H16=""),0,IF(DATE(2027,7,1)>=DATE(YEAR(G16),MONTH(G16),1),H16/12,0)) -> 77000 | AB16: =IF(OR(G16="",H16=""),0,IF(DATE(2027,8,1)>=DATE(YEAR(G16),MONTH(G16),1),H16/12,0)) -> 77000 | AC16: =IF(OR(G16="",H16=""),0,IF(DATE(2027,9,1)>=DATE(YEAR(G16),MONTH(G16),1),H16/12,0)) -> 77000 | AD16: =IF(OR(G16="",H16=""),0,IF(DATE(2027,10,1)>=DATE(YEAR(G16),MONTH(G16),1),H16/12,0)) -> 77000 | AE16: =IF(OR(G16="",H16=""),0,IF(DATE(2027,11,1)>=DATE(YEAR(G16),MONTH(G16),1),H16/12,0)) -> 77000 | AF16: =IF(OR(G16="",H16=""),0,IF(DATE(2027,12,1)>=DATE(YEAR(G16),MONTH(G16),1),H16/12,0)) -> 77000 | AG16: =SUM(U16:AF16) -> 924000 | AH16: =T16+AG16 -> 1463000 | AI16: =IF(OR(E16="",AH16=""),"",E16*AH16) -> 1097250 | AJ16: =IF('Pipeline Data Input'!M13="","",'Pipeline Data Input'!M13) -> Opp: JAS/WH/JUB/1400PP | Region: East
A17: 12 | B17: =IF('Pipeline Data Input'!D14="","",'Pipeline Data Input'!D14) -> LX Pantos Logistics | C17: =IF('Pipeline Data Input'!E14="","",'Pipeline Data Input'!E14) -> Yazan Darwish | D17: =IF('Pipeline Data Input'!J14="","",'Pipeline Data Input'!J14) -> Shortlisted | E17: =IFERROR(VLOOKUP(D17,$B$211:$C$217,2,FALSE()),0) -> 0.75 | F17: =IF('Pipeline Data Input'!B14="","",IFERROR(VLOOKUP('Pipeline Data Input'!B14,'Pipeline Data Input'!$A$66:$B$80,2,FALSE()),'Pipeline Data Input'!B14)) -> Jubail 1 | G17: =IF('Pipeline Data Input'!K14="","",'Pipeline Data Input'!K14) -> 46143 | H17: =IF('Pipeline Data Input'!I14="",0,'Pipeline Data Input'!I14) -> 726000 | I17: =T17 -> 484000 | J17: =IF('Pipeline Data Input'!F14="",0,'Pipeline Data Input'!F14) -> 1000 | K17: =IF('Pipeline Data Input'!G14="",0,'Pipeline Data Input'!G14) -> 0 | L17: =IF(OR(G17="",H17=""),0,IF(DATE(2026,5,1)>=DATE(YEAR(G17),MONTH(G17),1),H17/12,0)) -> 60500 | M17: =IF(OR(G17="",H17=""),0,IF(DATE(2026,6,1)>=DATE(YEAR(G17),MONTH(G17),1),H17/12,0)) -> 60500 | N17: =IF(OR(G17="",H17=""),0,IF(DATE(2026,7,1)>=DATE(YEAR(G17),MONTH(G17),1),H17/12,0)) -> 60500 | O17: =IF(OR(G17="",H17=""),0,IF(DATE(2026,8,1)>=DATE(YEAR(G17),MONTH(G17),1),H17/12,0)) -> 60500 | P17: =IF(OR(G17="",H17=""),0,IF(DATE(2026,9,1)>=DATE(YEAR(G17),MONTH(G17),1),H17/12,0)) -> 60500 | Q17: =IF(OR(G17="",H17=""),0,IF(DATE(2026,10,1)>=DATE(YEAR(G17),MONTH(G17),1),H17/12,0)) -> 60500 | R17: =IF(OR(G17="",H17=""),0,IF(DATE(2026,11,1)>=DATE(YEAR(G17),MONTH(G17),1),H17/12,0)) -> 60500 | S17: =IF(OR(G17="",H17=""),0,IF(DATE(2026,12,1)>=DATE(YEAR(G17),MONTH(G17),1),H17/12,0)) -> 60500 | T17: =SUM(L17:S17) -> 484000 | U17: =IF(OR(G17="",H17=""),0,IF(DATE(2027,1,1)>=DATE(YEAR(G17),MONTH(G17),1),H17/12,0)) -> 60500 | V17: =IF(OR(G17="",H17=""),0,IF(DATE(2027,2,1)>=DATE(YEAR(G17),MONTH(G17),1),H17/12,0)) -> 60500 | W17: =IF(OR(G17="",H17=""),0,IF(DATE(2027,3,1)>=DATE(YEAR(G17),MONTH(G17),1),H17/12,0)) -> 60500 | X17: =IF(OR(G17="",H17=""),0,IF(DATE(2027,4,1)>=DATE(YEAR(G17),MONTH(G17),1),H17/12,0)) -> 60500 | Y17: =IF(OR(G17="",H17=""),0,IF(DATE(2027,5,1)>=DATE(YEAR(G17),MONTH(G17),1),H17/12,0)) -> 60500 | Z17: =IF(OR(G17="",H17=""),0,IF(DATE(2027,6,1)>=DATE(YEAR(G17),MONTH(G17),1),H17/12,0)) -> 60500 | AA17: =IF(OR(G17="",H17=""),0,IF(DATE(2027,7,1)>=DATE(YEAR(G17),MONTH(G17),1),H17/12,0)) -> 60500 | AB17: =IF(OR(G17="",H17=""),0,IF(DATE(2027,8,1)>=DATE(YEAR(G17),MONTH(G17),1),H17/12,0)) -> 60500 | AC17: =IF(OR(G17="",H17=""),0,IF(DATE(2027,9,1)>=DATE(YEAR(G17),MONTH(G17),1),H17/12,0)) -> 60500 | AD17: =IF(OR(G17="",H17=""),0,IF(DATE(2027,10,1)>=DATE(YEAR(G17),MONTH(G17),1),H17/12,0)) -> 60500 | AE17: =IF(OR(G17="",H17=""),0,IF(DATE(2027,11,1)>=DATE(YEAR(G17),MONTH(G17),1),H17/12,0)) -> 60500 | AF17: =IF(OR(G17="",H17=""),0,IF(DATE(2027,12,1)>=DATE(YEAR(G17),MONTH(G17),1),H17/12,0)) -> 60500 | AG17: =SUM(U17:AF17) -> 726000 | AH17: =T17+AG17 -> 1210000 | AI17: =IF(OR(E17="",AH17=""),"",E17*AH17) -> 907500 | AJ17: =IF('Pipeline Data Input'!M14="","",'Pipeline Data Input'!M14) -> Opp: LXPantos/WH/JUB1/1000PP | Region: East
... A65: 60 | B65: =IF('Pipeline Data Input'!D62="","",'Pipeline Data Input'!D62) | C65: =IF('Pipeline Data Input'!E62="","",'Pipeline Data Input'!E62) | D65: =IF('Pipeline Data Input'!J62="","",'Pipeline Data Input'!J62) | E65: =IFERROR(VLOOKUP(D65,$B$211:$C$217,2,FALSE()),0) -> 0 | F65: =IF('Pipeline Data Input'!B62="","",IFERROR(VLOOKUP('Pipeline Data Input'!B62,'Pipeline Data Input'!$A$66:$B$80,2,FALSE()),'Pipeline Data Input'!B62)) | G65: =IF('Pipeline Data Input'!K62="","",'Pipeline Data Input'!K62) | H65: =IF('Pipeline Data Input'!I62="",0,'Pipeline Data Input'!I62) -> 0 | I65: =T65 -> 0 | J65: =IF('Pipeline Data Input'!F62="",0,'Pipeline Data Input'!F62) -> 0 | K65: =IF('Pipeline Data Input'!G62="",0,'Pipeline Data Input'!G62) -> 0 | L65: =IF(OR(G65="",H65=""),0,IF(DATE(2026,5,1)>=DATE(YEAR(G65),MONTH(G65),1),H65/12,0)) -> 0 | M65: =IF(OR(G65="",H65=""),0,IF(DATE(2026,6,1)>=DATE(YEAR(G65),MONTH(G65),1),H65/12,0)) -> 0 | N65: =IF(OR(G65="",H65=""),0,IF(DATE(2026,7,1)>=DATE(YEAR(G65),MONTH(G65),1),H65/12,0)) -> 0 | O65: =IF(OR(G65="",H65=""),0,IF(DATE(2026,8,1)>=DATE(YEAR(G65),MONTH(G65),1),H65/12,0)) -> 0 | P65: =IF(OR(G65="",H65=""),0,IF(DATE(2026,9,1)>=DATE(YEAR(G65),MONTH(G65),1),H65/12,0)) -> 0 | Q65: =IF(OR(G65="",H65=""),0,IF(DATE(2026,10,1)>=DATE(YEAR(G65),MONTH(G65),1),H65/12,0)) -> 0 | R65: =IF(OR(G65="",H65=""),0,IF(DATE(2026,11,1)>=DATE(YEAR(G65),MONTH(G65),1),H65/12,0)) -> 0 | S65: =IF(OR(G65="",H65=""),0,IF(DATE(2026,12,1)>=DATE(YEAR(G65),MONTH(G65),1),H65/12,0)) -> 0 | T65: =SUM(L65:S65) -> 0 | U65: =IF(OR(G65="",H65=""),0,IF(DATE(2027,1,1)>=DATE(YEAR(G65),MONTH(G65),1),H65/12,0)) -> 0 | V65: =IF(OR(G65="",H65=""),0,IF(DATE(2027,2,1)>=DATE(YEAR(G65),MONTH(G65),1),H65/12,0)) -> 0 | W65: =IF(OR(G65="",H65=""),0,IF(DATE(2027,3,1)>=DATE(YEAR(G65),MONTH(G65),1),H65/12,0)) -> 0 | X65: =IF(OR(G65="",H65=""),0,IF(DATE(2027,4,1)>=DATE(YEAR(G65),MONTH(G65),1),H65/12,0)) -> 0 | Y65: =IF(OR(G65="",H65=""),0,IF(DATE(2027,5,1)>=DATE(YEAR(G65),MONTH(G65),1),H65/12,0)) -> 0 | Z65: =IF(OR(G65="",H65=""),0,IF(DATE(2027,6,1)>=DATE(YEAR(G65),MONTH(G65),1),H65/12,0)) -> 0 | AA65: =IF(OR(G65="",H65=""),0,IF(DATE(2027,7,1)>=DATE(YEAR(G65),MONTH(G65),1),H65/12,0)) -> 0 | AB65: =IF(OR(G65="",H65=""),0,IF(DATE(2027,8,1)>=DATE(YEAR(G65),MONTH(G65),1),H65/12,0)) -> 0 | AC65: =IF(OR(G65="",H65=""),0,IF(DATE(2027,9,1)>=DATE(YEAR(G65),MONTH(G65),1),H65/12,0)) -> 0 | AD65: =IF(OR(G65="",H65=""),0,IF(DATE(2027,10,1)>=DATE(YEAR(G65),MONTH(G65),1),H65/12,0)) -> 0 | AE65: =IF(OR(G65="",H65=""),0,IF(DATE(2027,11,1)>=DATE(YEAR(G65),MONTH(G65),1),H65/12,0)) -> 0 | AF65: =IF(OR(G65="",H65=""),0,IF(DATE(2027,12,1)>=DATE(YEAR(G65),MONTH(G65),1),H65/12,0)) -> 0 | AG65: =SUM(U65:AF65) -> 0 | AH65: =T65+AG65 -> 0 | AI65: =IF(OR(E65="",AH65=""),"",E65*AH65) -> 0 | AJ65: =IF('Pipeline Data Input'!M62="","",'Pipeline Data Input'!M62)
B66: TOTAL PIPELINE (Unweighted) | H66: =SUM(H6:H65) -> 42367332 | I66: =SUM(I6:I65) -> 21328363 | J66: =SUM(J6:J65) -> 49820 | K66: =SUM(K6:K65) -> 26145 | L66: =SUM(L6:L65) -> 1016669.3 | M66: =SUM(M6:M65) -> 1696194.3 | N66: =SUM(N6:N65) -> 2678777.7 | O66: =SUM(O6:O65) -> 2831277.7 | ... S66: =SUM(S6:S65) -> 3530611 | T66: =SUM(L66:S66) -> 21328363 | U66: =SUM(U6:U65) -> 3530611 | V66: =SUM(V6:V65) -> 3530611 | W66: =SUM(W6:W65) -> 3530611 | X66: =SUM(X6:X65) -> 3530611 | Y66: =SUM(Y6:Y65) -> 3530611 | Z66: =SUM(Z6:Z65) -> 3530611 | AA66: =SUM(AA6:AA65) -> 3530611 | AB66: =SUM(AB6:AB65) -> 3530611 | ... AF66: =SUM(AF6:AF65) -> 3530611 | AG66: =SUM(U66:AF66) -> 42367332 | AH66: =T66+AG66 -> 63695695
B67: TOTAL PIPELINE (Probability-Weighted) | H67: =SUMPRODUCT(E6:E65,H6:H65) -> 28448479 | I67: =SUMPRODUCT(E6:E65,I6:I65) -> 14884234 | J67: =SUM(J6:J65) -> 49820 | K67: =SUM(K6:K65) -> 26145 | L67: =SUMPRODUCT(E6:E65,L6:L65) -> 861463.27 | M67: =SUMPRODUCT(E6:E65,M6:M65) -> 1339431.6 | N67: =SUMPRODUCT(E6:E65,N6:N65) -> 1859606.6 | O67: =SUMPRODUCT(E6:E65,O6:O65) -> 1951106.6 | P67: =SUMPRODUCT(E6:E65,P6:P65) -> 2065606.6 | Q67: =SUMPRODUCT(E6:E65,Q6:Q65) -> 2065606.6 | R67: =SUMPRODUCT(E6:E65,R6:R65) -> 2370706.6 | S67: =SUMPRODUCT(E6:E65,S6:S65) -> 2370706.6 | T67: =SUM(L67:S67) -> 14884234 | U67: =SUMPRODUCT(E6:E65,U6:U65) -> 2370706.6 | V67: =SUMPRODUCT(E6:E65,V6:V65) -> 2370706.6 | W67: =SUMPRODUCT(E6:E65,W6:W65) -> 2370706.6 | X67: =SUMPRODUCT(E6:E65,X6:X65) -> 2370706.6 | Y67: =SUMPRODUCT(E6:E65,Y6:Y65) -> 2370706.6 | Z67: =SUMPRODUCT(E6:E65,Z6:Z65) -> 2370706.6 | AA67: =SUMPRODUCT(E6:E65,AA6:AA65) -> 2370706.6 | AB67: =SUMPRODUCT(E6:E65,AB6:AB65) -> 2370706.6 | AC67: =SUMPRODUCT(E6:E65,AC6:AC65) -> 2370706.6 | AD67: =SUMPRODUCT(E6:E65,AD6:AD65) -> 2370706.6 | AE67: =SUMPRODUCT(E6:E65,AE6:AE65) -> 2370706.6 | AF67: =SUMPRODUCT(E6:E65,AF6:AF65) -> 2370706.6 | AG67: =SUM(U67:AF67) -> 28448479 | AH67: =T67+AG67 -> 43332714
A69: 2. COST PROJECTIONS (Cost % per deal × Revenue ACV; monthly cells follow Go-Live)
A70: # | B70: Customer / Cost Item | C70: Opportunity Owner | D70: Stage | E70: Probability | F70: Warehouse Location | G70: Ops Go-Live Date | H70: Cost % | I70: Annual Cost (Projected) | J70: Volume - Pallets | K70: Volume - SQM | L70: May-26 | M70: Jun-26 | N70: Jul-26 | O70: Aug-26 | P70: Sep-26 | Q70: Oct-26 | R70: Nov-26 | S70: Dec-26 | T70: 2026 Total | U70: Jan-27 | V70: Feb-27 | W70: Mar-27 | X70: Apr-27 | Y70: May-27 | Z70: Jun-27 | AA70: Jul-27 | AB70: Aug-27 | AC70: Sep-27 | AD70: Oct-27 | AE70: Nov-27 | AF70: Dec-27 | AG70: 2027 Total | AH70: Grand Total | AI70: Weighted Total | AJ70: Notes
A71: 1 | B71: =IF(B6="","",B6) -> SLB | C71: =IF(C6="","",C6) -> Yazan Darwish | D71: =IF(D6="","",D6) -> Prospecting | E71: =IF(E6="","",E6) -> 0.2 | F71: =IF(F6="","",F6) -> Dammam 2nd Ind -Tad WH | G71: =IF(G6="","",G6) -> 46204 | H71: 0.75 | I71: =IF(OR(H71="",H6=""),0,H71*H6) -> 1800000 | J71: =IF(J6="","",J6) -> 4000 | K71: =IF(K6="","",K6) -> 0 | L71: =IF(OR(G71="",I71=0),0,IF(DATE(2026,5,1)>=DATE(YEAR(G71),MONTH(G71),1),I71/12,0)) -> 0 | M71: =IF(OR(G71="",I71=0),0,IF(DATE(2026,6,1)>=DATE(YEAR(G71),MONTH(G71),1),I71/12,0)) -> 0 | N71: =IF(OR(G71="",I71=0),0,IF(DATE(2026,7,1)>=DATE(YEAR(G71),MONTH(G71),1),I71/12,0)) -> 150000 | O71: =IF(OR(G71="",I71=0),0,IF(DATE(2026,8,1)>=DATE(YEAR(G71),MONTH(G71),1),I71/12,0)) -> 150000 | P71: =IF(OR(G71="",I71=0),0,IF(DATE(2026,9,1)>=DATE(YEAR(G71),MONTH(G71),1),I71/12,0)) -> 150000 | Q71: =IF(OR(G71="",I71=0),0,IF(DATE(2026,10,1)>=DATE(YEAR(G71),MONTH(G71),1),I71/12,0)) -> 150000 | R71: =IF(OR(G71="",I71=0),0,IF(DATE(2026,11,1)>=DATE(YEAR(G71),MONTH(G71),1),I71/12,0)) -> 150000 | S71: =IF(OR(G71="",I71=0),0,IF(DATE(2026,12,1)>=DATE(YEAR(G71),MONTH(G71),1),I71/12,0)) -> 150000 | T71: =SUM(L71:S71) -> 900000 | U71: =IF(OR(G71="",I71=0),0,IF(DATE(2027,1,1)>=DATE(YEAR(G71),MONTH(G71),1),I71/12,0)) -> 150000 | V71: =IF(OR(G71="",I71=0),0,IF(DATE(2027,2,1)>=DATE(YEAR(G71),MONTH(G71),1),I71/12,0)) -> 150000 | W71: =IF(OR(G71="",I71=0),0,IF(DATE(2027,3,1)>=DATE(YEAR(G71),MONTH(G71),1),I71/12,0)) -> 150000 | X71: =IF(OR(G71="",I71=0),0,IF(DATE(2027,4,1)>=DATE(YEAR(G71),MONTH(G71),1),I71/12,0)) -> 150000 | Y71: =IF(OR(G71="",I71=0),0,IF(DATE(2027,5,1)>=DATE(YEAR(G71),MONTH(G71),1),I71/12,0)) -> 150000 | Z71: =IF(OR(G71="",I71=0),0,IF(DATE(2027,6,1)>=DATE(YEAR(G71),MONTH(G71),1),I71/12,0)) -> 150000 | AA71: =IF(OR(G71="",I71=0),0,IF(DATE(2027,7,1)>=DATE(YEAR(G71),MONTH(G71),1),I71/12,0)) -> 150000 | AB71: =IF(OR(G71="",I71=0),0,IF(DATE(2027,8,1)>=DATE(YEAR(G71),MONTH(G71),1),I71/12,0)) -> 150000 | AC71: =IF(OR(G71="",I71=0),0,IF(DATE(2027,9,1)>=DATE(YEAR(G71),MONTH(G71),1),I71/12,0)) -> 150000 | AD71: =IF(OR(G71="",I71=0),0,IF(DATE(2027,10,1)>=DATE(YEAR(G71),MONTH(G71),1),I71/12,0)) -> 150000 | AE71: =IF(OR(G71="",I71=0),0,IF(DATE(2027,11,1)>=DATE(YEAR(G71),MONTH(G71),1),I71/12,0)) -> 150000 | AF71: =IF(OR(G71="",I71=0),0,IF(DATE(2027,12,1)>=DATE(YEAR(G71),MONTH(G71),1),I71/12,0)) -> 150000 | AG71: =SUM(U71:AF71) -> 1800000 | AH71: =T71+AG71 -> 2700000 | AI71: =IF(OR(E71="",AH71=""),"",E71*AH71) -> 540000
